<?xml version="1.0" encoding="UTF-8"?>
<!-- Generated by org.testng.reporters.JUnitXMLReporter -->
<testsuite hostname="丁枝" ignored="0" name="丁枝的测试模块" tests="4" failures="2" timestamp="06 四月 2020 08:00:32 GMT" time="0.026" errors="0">
  <testcase name="test1" time="0.006" classname="com.tester.extent.demo.TestMethodDemo">
    <failure type="java.lang.AssertionError" message="expected [23333] but found [1]">
      <![CDATA[java.lang.AssertionError: expected [23333] but found [1]
	at com.tester.extent.demo.TestMethodDemo.test1(TestMethodDemo.java:10)
	at com.intellij.rt.testng.IDEARemoteTestNG.run(IDEARemoteTestNG.java:66)
	at com.intellij.rt.testng.RemoteTestNGStarter.main(RemoteTestNGStarter.java:110)
... Removed 28 stack frames]]>
    </failure>
  </testcase> <!-- test1 -->
  <testcase name="test2" time="0.0" classname="com.tester.extent.demo.TestMethodDemo"/>
  <testcase name="test3" time="0.001" classname="com.tester.extent.demo.TestMethodDemo"/>
  <testcase name="logDemo" time="0.0" classname="com.tester.extent.demo.TestMethodDemo">
    <failure type="java.lang.RuntimeException" message="这是自己的运行异常">
      <![CDATA[java.lang.RuntimeException: 这是自己的运行异常
	at com.tester.extent.demo.TestMethodDemo.logDemo(TestMethodDemo.java:23)
	at com.intellij.rt.testng.IDEARemoteTestNG.run(IDEARemoteTestNG.java:66)
	at com.intellij.rt.testng.RemoteTestNGStarter.main(RemoteTestNGStarter.java:110)
... Removed 22 stack frames]]>
    </failure>
  </testcase> <!-- logDemo -->
</testsuite> <!-- 丁枝的测试模块 -->
